[31/Oct/2017 22:49:50] ERROR [django.request:256] Internal Server Error: /
Traceback (most recent call last):
  File "/home/jimmy/.virtualenvs/jc_dev/lib/python3.5/site-packages/django/core/urlresolvers.py", line 105, in get_callable
    mod = import_module(mod_name)
  File "/home/jimmy/.virtualenvs/jc_dev/lib/python3.5/importlib/__init__.py", line 126, in import_module
    return _bootstrap._gcd_import(name[level:], package, level)
  File "<frozen importlib._bootstrap>", line 986, in _gcd_import
  File "<frozen importlib._bootstrap>", line 969, in _find_and_load
  File "<frozen importlib._bootstrap>", line 956, in _find_and_load_unlocked
ImportError: No module named 'tdeecalculator.views'

During handling of the above exception, another exception occurred:

Traceback (most recent call last):
  File "/home/jimmy/.virtualenvs/jc_dev/lib/python3.5/site-packages/django/core/handlers/base.py", line 119, in get_response
    resolver_match = resolver.resolve(request.path_info)
  File "/home/jimmy/.virtualenvs/jc_dev/lib/python3.5/site-packages/django/core/urlresolvers.py", line 367, in resolve
    sub_match = pattern.resolve(new_path)
  File "/home/jimmy/.virtualenvs/jc_dev/lib/python3.5/site-packages/django/core/urlresolvers.py", line 239, in resolve
    return ResolverMatch(self.callback, args, kwargs, self.name)
  File "/home/jimmy/.virtualenvs/jc_dev/lib/python3.5/site-packages/django/core/urlresolvers.py", line 246, in callback
    self._callback = get_callable(self._callback_str)
  File "/home/jimmy/.virtualenvs/jc_dev/lib/python3.5/site-packages/django/core/urlresolvers.py", line 114, in get_callable
    (lookup_view, mod_name))
django.core.exceptions.ViewDoesNotExist: Could not import 'tdeecalculator.views.home'. Parent module tdeecalculator.views does not exist.
[31/Oct/2017 22:50:01] ERROR [django.request:256] Internal Server Error: /
Traceback (most recent call last):
  File "/home/jimmy/.virtualenvs/jc_dev/lib/python3.5/site-packages/django/core/urlresolvers.py", line 105, in get_callable
    mod = import_module(mod_name)
  File "/home/jimmy/.virtualenvs/jc_dev/lib/python3.5/importlib/__init__.py", line 126, in import_module
    return _bootstrap._gcd_import(name[level:], package, level)
  File "<frozen importlib._bootstrap>", line 986, in _gcd_import
  File "<frozen importlib._bootstrap>", line 969, in _find_and_load
  File "<frozen importlib._bootstrap>", line 956, in _find_and_load_unlocked
ImportError: No module named 'tdeecalculator.views'

During handling of the above exception, another exception occurred:

Traceback (most recent call last):
  File "/home/jimmy/.virtualenvs/jc_dev/lib/python3.5/site-packages/django/core/handlers/base.py", line 119, in get_response
    resolver_match = resolver.resolve(request.path_info)
  File "/home/jimmy/.virtualenvs/jc_dev/lib/python3.5/site-packages/django/core/urlresolvers.py", line 367, in resolve
    sub_match = pattern.resolve(new_path)
  File "/home/jimmy/.virtualenvs/jc_dev/lib/python3.5/site-packages/django/core/urlresolvers.py", line 239, in resolve
    return ResolverMatch(self.callback, args, kwargs, self.name)
  File "/home/jimmy/.virtualenvs/jc_dev/lib/python3.5/site-packages/django/core/urlresolvers.py", line 246, in callback
    self._callback = get_callable(self._callback_str)
  File "/home/jimmy/.virtualenvs/jc_dev/lib/python3.5/site-packages/django/core/urlresolvers.py", line 114, in get_callable
    (lookup_view, mod_name))
django.core.exceptions.ViewDoesNotExist: Could not import 'tdeecalculator.views.home'. Parent module tdeecalculator.views does not exist.
